2025-02-28 13:18:18,519 ERROR: Exception on / [GET] [in C:\Users\Olga\PycharmProjects\Flask_book\.venv\Lib\site-packages\flask\app.py:875]
Traceback (most recent call last):
  File "C:\Users\Olga\PycharmProjects\Flask_book\.venv\Lib\site-packages\sqlalchemy\engine\base.py", line 1964, in _exec_single_context
    self.dialect.do_execute(
    ~~~~~~~~~~~~~~~~~~~~~~~^
        cursor, str_statement, effective_parameters, context
        ^^^^^^^^^^^^^^^^^^^^^^^^^^^^^^^^^^^^^^^^^^^^^^^^^^^^
    )
    ^
  File "C:\Users\Olga\PycharmProjects\Flask_book\.venv\Lib\site-packages\sqlalchemy\engine\default.py", line 942, in do_execute
    cursor.execute(statement, parameters)
    ~~~~~~~~~~~~~~^^^^^^^^^^^^^^^^^^^^^^^
sqlite3.OperationalError: no such column: post.timestamp

The above exception was the direct cause of the following exception:

Traceback (most recent call last):
  File "C:\Users\Olga\PycharmProjects\Flask_book\.venv\Lib\site-packages\flask\app.py", line 1511, in wsgi_app
    response = self.full_dispatch_request()
  File "C:\Users\Olga\PycharmProjects\Flask_book\.venv\Lib\site-packages\flask\app.py", line 919, in full_dispatch_request
    rv = self.handle_user_exception(e)
  File "C:\Users\Olga\PycharmProjects\Flask_book\.venv\Lib\site-packages\flask\app.py", line 917, in full_dispatch_request
    rv = self.dispatch_request()
  File "C:\Users\Olga\PycharmProjects\Flask_book\.venv\Lib\site-packages\flask\app.py", line 902, in dispatch_request
    return self.ensure_sync(self.view_functions[rule.endpoint])(**view_args)  # type: ignore[no-any-return]
           ~~~~~~~~~~~~~~~~~~~~~~~~~~~~~~~~~~~~~~~~~~~~~~~~~~~~^^^^^^^^^^^^^
  File "C:\Users\Olga\PycharmProjects\Flask_book\.venv\Lib\site-packages\flask_login\utils.py", line 290, in decorated_view
    return current_app.ensure_sync(func)(*args, **kwargs)
           ~~~~~~~~~~~~~~~~~~~~~~~~~~~~~^^^^^^^^^^^^^^^^^
  File "C:\Users\Olga\PycharmProjects\Flask_book\app\routes.py", line 24, in index
    posts = db.session.scalars(current_user.following_posts()).all()
            ~~~~~~~~~~~~~~~~~~^^^^^^^^^^^^^^^^^^^^^^^^^^^^^^^^
  File "C:\Users\Olga\PycharmProjects\Flask_book\.venv\Lib\site-packages\sqlalchemy\orm\scoping.py", line 1906, in scalars
    return self._proxied.scalars(
           ~~~~~~~~~~~~~~~~~~~~~^
        statement,
        ^^^^^^^^^^
    ...<3 lines>...
        **kw,
        ^^^^^
    )
    ^
  File "C:\Users\Olga\PycharmProjects\Flask_book\.venv\Lib\site-packages\sqlalchemy\orm\session.py", line 2473, in scalars
    return self._execute_internal(
           ~~~~~~~~~~~~~~~~~~~~~~^
        statement,
        ^^^^^^^^^^
    ...<4 lines>...
        **kw,
        ^^^^^
    ).scalars()
    ^
  File "C:\Users\Olga\PycharmProjects\Flask_book\.venv\Lib\site-packages\sqlalchemy\orm\session.py", line 2251, in _execute_internal
    result: Result[Any] = compile_state_cls.orm_execute_statement(
                          ~~~~~~~~~~~~~~~~~~~~~~~~~~~~~~~~~~~~~~~^
        self,
        ^^^^^
    ...<4 lines>...
        conn,
        ^^^^^
    )
    ^
  File "C:\Users\Olga\PycharmProjects\Flask_book\.venv\Lib\site-packages\sqlalchemy\orm\context.py", line 305, in orm_execute_statement
    result = conn.execute(
        statement, params or {}, execution_options=execution_options
    )
  File "C:\Users\Olga\PycharmProjects\Flask_book\.venv\Lib\site-packages\sqlalchemy\engine\base.py", line 1416, in execute
    return meth(
        self,
        distilled_parameters,
        execution_options or NO_OPTIONS,
    )
  File "C:\Users\Olga\PycharmProjects\Flask_book\.venv\Lib\site-packages\sqlalchemy\sql\elements.py", line 516, in _execute_on_connection
    return connection._execute_clauseelement(
           ~~~~~~~~~~~~~~~~~~~~~~~~~~~~~~~~~^
        self, distilled_params, execution_options
        ^^^^^^^^^^^^^^^^^^^^^^^^^^^^^^^^^^^^^^^^^
    )
    ^
  File "C:\Users\Olga\PycharmProjects\Flask_book\.venv\Lib\site-packages\sqlalchemy\engine\base.py", line 1638, in _execute_clauseelement
    ret = self._execute_context(
        dialect,
    ...<8 lines>...
        cache_hit=cache_hit,
    )
  File "C:\Users\Olga\PycharmProjects\Flask_book\.venv\Lib\site-packages\sqlalchemy\engine\base.py", line 1843, in _execute_context
    return self._exec_single_context(
           ~~~~~~~~~~~~~~~~~~~~~~~~~^
        dialect, context, statement, parameters
        ^^^^^^^^^^^^^^^^^^^^^^^^^^^^^^^^^^^^^^^
    )
    ^
  File "C:\Users\Olga\PycharmProjects\Flask_book\.venv\Lib\site-packages\sqlalchemy\engine\base.py", line 1983, in _exec_single_context
    self._handle_dbapi_exception(
    ~~~~~~~~~~~~~~~~~~~~~~~~~~~~^
        e, str_statement, effective_parameters, cursor, context
        ^^^^^^^^^^^^^^^^^^^^^^^^^^^^^^^^^^^^^^^^^^^^^^^^^^^^^^^
    )
    ^
  File "C:\Users\Olga\PycharmProjects\Flask_book\.venv\Lib\site-packages\sqlalchemy\engine\base.py", line 2352, in _handle_dbapi_exception
    raise sqlalchemy_exception.with_traceback(exc_info[2]) from e
  File "C:\Users\Olga\PycharmProjects\Flask_book\.venv\Lib\site-packages\sqlalchemy\engine\base.py", line 1964, in _exec_single_context
    self.dialect.do_execute(
    ~~~~~~~~~~~~~~~~~~~~~~~^
        cursor, str_statement, effective_parameters, context
        ^^^^^^^^^^^^^^^^^^^^^^^^^^^^^^^^^^^^^^^^^^^^^^^^^^^^
    )
    ^
  File "C:\Users\Olga\PycharmProjects\Flask_book\.venv\Lib\site-packages\sqlalchemy\engine\default.py", line 942, in do_execute
    cursor.execute(statement, parameters)
    ~~~~~~~~~~~~~~^^^^^^^^^^^^^^^^^^^^^^^
sqlalchemy.exc.OperationalError: (sqlite3.OperationalError) no such column: post.timestamp
[SQL: SELECT post.id, post.body, post.timestamp, post.user_id 
FROM post JOIN user AS user_1 ON user_1.id = post.user_id LEFT OUTER JOIN (followers AS followers_1 JOIN user AS user_2 ON followers_1.follower_id = user_2.id) ON followers_1.followed_id = user_1.id 
WHERE user_2.id = ? OR user_1.id = ? GROUP BY post.id, post.body, post.timestamp, post.user_id ORDER BY post.timestamp DESC]
[parameters: (1, 1)]
(Background on this error at: https://sqlalche.me/e/20/e3q8)
2025-02-28 13:54:35,586 INFO: My project [in C:\Users\Olga\PycharmProjects\Flask_book\app\__init__.py:41]
2025-02-28 15:07:47,791 INFO: My project [in C:\Users\Olga\PycharmProjects\Flask_book\app\__init__.py:41]
2025-02-28 15:08:03,121 INFO: My project [in C:\Users\Olga\PycharmProjects\Flask_book\app\__init__.py:41]
2025-02-28 15:13:47,122 INFO: My project [in C:\Users\Olga\PycharmProjects\Flask_book\app\__init__.py:41]
2025-02-28 15:26:08,124 INFO: My project [in C:\Users\Olga\PycharmProjects\Flask_book\app\__init__.py:41]
2025-03-04 13:19:41,998 INFO: My project [in C:\Users\Olga\PycharmProjects\Flask_book\app\__init__.py:43]
2025-03-04 15:59:26,296 INFO: My project [in C:\Users\Olga\PycharmProjects\Flask_book\app\__init__.py:43]
2025-03-04 15:59:38,912 ERROR: Exception on /reset_password_request [GET] [in C:\Users\Olga\PycharmProjects\Flask_book\.venv\Lib\site-packages\flask\app.py:875]
Traceback (most recent call last):
  File "C:\Users\Olga\PycharmProjects\Flask_book\.venv\Lib\site-packages\flask\app.py", line 1511, in wsgi_app
    response = self.full_dispatch_request()
  File "C:\Users\Olga\PycharmProjects\Flask_book\.venv\Lib\site-packages\flask\app.py", line 919, in full_dispatch_request
    rv = self.handle_user_exception(e)
  File "C:\Users\Olga\PycharmProjects\Flask_book\.venv\Lib\site-packages\flask\app.py", line 917, in full_dispatch_request
    rv = self.dispatch_request()
  File "C:\Users\Olga\PycharmProjects\Flask_book\.venv\Lib\site-packages\flask\app.py", line 902, in dispatch_request
    return self.ensure_sync(self.view_functions[rule.endpoint])(**view_args)  # type: ignore[no-any-return]
           ~~~~~~~~~~~~~~~~~~~~~~~~~~~~~~~~~~~~~~~~~~~~~~~~~~~~^^^^^^^^^^^^^
  File "C:\Users\Olga\PycharmProjects\Flask_book\app\routes.py", line 162, in reset_password_request
    return render_template('reset_password_request.html', title='Reset Password', form=form)
  File "C:\Users\Olga\PycharmProjects\Flask_book\.venv\Lib\site-packages\flask\templating.py", line 149, in render_template
    template = app.jinja_env.get_or_select_template(template_name_or_list)
  File "C:\Users\Olga\PycharmProjects\Flask_book\.venv\Lib\site-packages\jinja2\environment.py", line 1087, in get_or_select_template
    return self.get_template(template_name_or_list, parent, globals)
           ~~~~~~~~~~~~~~~~~^^^^^^^^^^^^^^^^^^^^^^^^^^^^^^^^^^^^^^^^
  File "C:\Users\Olga\PycharmProjects\Flask_book\.venv\Lib\site-packages\jinja2\environment.py", line 1016, in get_template
    return self._load_template(name, globals)
           ~~~~~~~~~~~~~~~~~~~^^^^^^^^^^^^^^^
  File "C:\Users\Olga\PycharmProjects\Flask_book\.venv\Lib\site-packages\jinja2\environment.py", line 975, in _load_template
    template = self.loader.load(self, name, self.make_globals(globals))
  File "C:\Users\Olga\PycharmProjects\Flask_book\.venv\Lib\site-packages\jinja2\loaders.py", line 138, in load
    code = environment.compile(source, name, filename)
  File "C:\Users\Olga\PycharmProjects\Flask_book\.venv\Lib\site-packages\jinja2\environment.py", line 771, in compile
    self.handle_exception(source=source_hint)
    ~~~~~~~~~~~~~~~~~~~~~^^^^^^^^^^^^^^^^^^^^
  File "C:\Users\Olga\PycharmProjects\Flask_book\.venv\Lib\site-packages\jinja2\environment.py", line 942, in handle_exception
    raise rewrite_traceback_stack(source=source)
  File "C:\Users\Olga\PycharmProjects\Flask_book\app\templates\reset_password_request.html", line 11, in template
    <span style="color: red;">[{{ error }]</span>
    ^^^^^^^^^^^^^^^^^
jinja2.exceptions.TemplateSyntaxError: unexpected '}'
2025-03-04 18:42:42,370 INFO: My project [in C:\Users\Olga\PycharmProjects\Flask_book\app\__init__.py:43]
