2025-03-04 18:43:17,260 ERROR: Exception on /reset_password_request [POST] [in C:\Users\Olga\PycharmProjects\Flask_book\.venv\Lib\site-packages\flask\app.py:875]
Traceback (most recent call last):
  File "C:\Users\Olga\PycharmProjects\Flask_book\.venv\Lib\site-packages\flask\app.py", line 1511, in wsgi_app
    response = self.full_dispatch_request()
  File "C:\Users\Olga\PycharmProjects\Flask_book\.venv\Lib\site-packages\flask\app.py", line 919, in full_dispatch_request
    rv = self.handle_user_exception(e)
  File "C:\Users\Olga\PycharmProjects\Flask_book\.venv\Lib\site-packages\flask\app.py", line 917, in full_dispatch_request
    rv = self.dispatch_request()
  File "C:\Users\Olga\PycharmProjects\Flask_book\.venv\Lib\site-packages\flask\app.py", line 902, in dispatch_request
    return self.ensure_sync(self.view_functions[rule.endpoint])(**view_args)  # type: ignore[no-any-return]
           ~~~~~~~~~~~~~~~~~~~~~~~~~~~~~~~~~~~~~~~~~~~~~~~~~~~~^^^^^^^^^^^^^
  File "C:\Users\Olga\PycharmProjects\Flask_book\app\routes.py", line 159, in reset_password_request
    send_password_reset_email(user)
    ~~~~~~~~~~~~~~~~~~~~~~~~~^^^^^^
  File "C:\Users\Olga\PycharmProjects\Flask_book\app\email.py", line 19, in send_password_reset_email
    html_body=render_template('email/reset_password.html', token=token))
              ~~~~~~~~~~~~~~~^^^^^^^^^^^^^^^^^^^^^^^^^^^^^^^^^^^^^^^^^^
  File "C:\Users\Olga\PycharmProjects\Flask_book\.venv\Lib\site-packages\flask\templating.py", line 150, in render_template
    return _render(app, template, context)
  File "C:\Users\Olga\PycharmProjects\Flask_book\.venv\Lib\site-packages\flask\templating.py", line 131, in _render
    rv = template.render(context)
  File "C:\Users\Olga\PycharmProjects\Flask_book\.venv\Lib\site-packages\jinja2\environment.py", line 1295, in render
    self.environment.handle_exception()
    ~~~~~~~~~~~~~~~~~~~~~~~~~~~~~~~~~^^
  File "C:\Users\Olga\PycharmProjects\Flask_book\.venv\Lib\site-packages\jinja2\environment.py", line 942, in handle_exception
    raise rewrite_traceback_stack(source=source)
  File "C:\Users\Olga\PycharmProjects\Flask_book\app\templates\email\reset_password.html", line 8, in top-level template code
    <p>Dear {{ user.username }},</p>
    ^^^^^^^^^^^^^^^^^^^^^^^
  File "C:\Users\Olga\PycharmProjects\Flask_book\.venv\Lib\site-packages\jinja2\environment.py", line 490, in getattr
    return getattr(obj, attribute)
jinja2.exceptions.UndefinedError: 'user' is undefined
2025-05-22 17:23:57,727 INFO: My project [in C:\Users\Olga\PycharmProjects\Flask_book_2\app\__init__.py:46]
2025-05-22 17:23:57,729 INFO: My project [in C:\Users\Olga\PycharmProjects\Flask_book_2\app\__init__.py:46]
2025-05-22 17:24:38,398 INFO: My project [in C:\Users\Olga\PycharmProjects\Flask_book_2\app\__init__.py:46]
2025-05-22 17:24:38,400 INFO: My project [in C:\Users\Olga\PycharmProjects\Flask_book_2\app\__init__.py:46]
2025-05-22 17:25:03,343 INFO: My project [in C:\Users\Olga\PycharmProjects\Flask_book_2\app\__init__.py:46]
2025-05-22 17:27:49,795 ERROR: Exception on /register [POST] [in C:\Users\Olga\AppData\Local\Programs\Python\Python39\lib\site-packages\flask\app.py:875]
Traceback (most recent call last):
  File "C:\Users\Olga\AppData\Local\Programs\Python\Python39\lib\site-packages\wtforms\validators.py", line 401, in __call__
    import email_validator
ModuleNotFoundError: No module named 'email_validator'

The above exception was the direct cause of the following exception:

Traceback (most recent call last):
  File "C:\Users\Olga\AppData\Local\Programs\Python\Python39\lib\site-packages\flask\app.py", line 1511, in wsgi_app
    response = self.full_dispatch_request()
  File "C:\Users\Olga\AppData\Local\Programs\Python\Python39\lib\site-packages\flask\app.py", line 919, in full_dispatch_request
    rv = self.handle_user_exception(e)
  File "C:\Users\Olga\AppData\Local\Programs\Python\Python39\lib\site-packages\flask\app.py", line 917, in full_dispatch_request
    rv = self.dispatch_request()
  File "C:\Users\Olga\AppData\Local\Programs\Python\Python39\lib\site-packages\flask\app.py", line 902, in dispatch_request
    return self.ensure_sync(self.view_functions[rule.endpoint])(**view_args)  # type: ignore[no-any-return]
  File "C:\Users\Olga\PycharmProjects\Flask_book_2\app\routes.py", line 66, in register
    if form.validate_on_submit():
  File "C:\Users\Olga\AppData\Local\Programs\Python\Python39\lib\site-packages\flask_wtf\form.py", line 86, in validate_on_submit
    return self.is_submitted() and self.validate(extra_validators=extra_validators)
  File "C:\Users\Olga\AppData\Local\Programs\Python\Python39\lib\site-packages\wtforms\form.py", line 330, in validate
    return super().validate(extra)
  File "C:\Users\Olga\AppData\Local\Programs\Python\Python39\lib\site-packages\wtforms\form.py", line 147, in validate
    if not field.validate(self, extra):
  File "C:\Users\Olga\AppData\Local\Programs\Python\Python39\lib\site-packages\wtforms\fields\core.py", line 234, in validate
    stop_validation = self._run_validation_chain(form, chain)
  File "C:\Users\Olga\AppData\Local\Programs\Python\Python39\lib\site-packages\wtforms\fields\core.py", line 254, in _run_validation_chain
    validator(form, self)
  File "C:\Users\Olga\AppData\Local\Programs\Python\Python39\lib\site-packages\wtforms\validators.py", line 403, in __call__
    raise Exception(
Exception: Install 'email_validator' for email validation support.
2025-05-29 12:53:40,428 INFO: My project [in C:\Users\Olga\PycharmProjects\Flask_book_2\app\__init__.py:50]
2025-05-29 12:54:50,010 INFO: My project [in C:\Users\Olga\PycharmProjects\Flask_book_2\app\__init__.py:50]
2025-05-29 12:55:54,942 INFO: My project [in C:\Users\Olga\PycharmProjects\Flask_book_2\app\__init__.py:50]
